Workbook

Sheet Order Summary
B2: Customer: | C2: Styl2000 | H2: Password | I2: €uro
B3: Enquiry Name | C3: Quote Trial 1
B4: Date:
W5: Connection System | AE5: Material Choice | AL5: Gauge Panels | AQ5: Field Panel | AV5: Rubber Edge Beam | AZ5: Chain Guard | BD5: End Restraint | BH5: 3.6m AEB | BM5: 1.8m AEB | BQ5: Connection Ancillary 1 | BU5: Connection Ancillary 2 | BY5: Connection Ancillary 3 | CC5: Connection Ancillary 4 Type | CG5: Connection Ancillary 5 Type | CK5: Connection Ancillary 6 Type | CO5: Connection Ancillary 7 Type | CS5: Rubber Edge Beam Baseplate
B6: Crossing Name | C6: Design Length | D6: RHR Length | E6: Number of Tracks | F6: Rail | G6: Sleeper | H6: Clip | I6: Rail Pad | J6: Isolation Pad | K6: Gauge (+Gauge Widening) | L6: Sleeper Spacings at 600mm? | M6: Crossing Angle | N6: Field Panel Type | O6: Edge Beam Type | P6: Road Speed(KM/h) | Q6: Crossing Usage | R6: Hidden Available Connection Type | S6: Available Connection Types | T6: Actual Connection Type | U6: Crossing Price | W6: Baseplated | X6: Loop Connect | Y6: Loop Interlocker | Z6: Link | AA6: Link Interlocker | AB6: TITAN | AC6: Strandlock | AE6: P(B) | AF6: A(B) | AG6: JV | AH6: N | AI6: TC | AJ6: Choice | AL6: GP Type | AM6: GP Code | AN6: GP Quantity | AO6: GP Price | AP6: Line Price | AQ6: FP Type | AR6: FP Code | AS6: FP Quantity | AT6: FP Price | AU6: Line Price | AV6: REB Code | AW6: REB Quantity | AX6: REB Price | AY6: Line Price | AZ6: CG Type | BA6: CG Quantity | BB6: CG Price | BC6: Line Price | BD6: ER Type | BE6: ER Quantity | BF6: ER Price | BG6: Line Price | BH6: AEB Type | BI6: AEB Quantity | BJ6: AEB Price | BK6: Line Price | BL6: AEB Type | BM6: AEB Quantity | BN6: AEB Price | BO6: Line Price | BP6: AEB Type | BQ6: Connection Ancillary Type | BR6: Connection Ancillary Quantity | BS6: Price | BT6: Line Price | BU6: Connection Ancillary 2 Type | BV6: Connection Ancillary 2 Quantity | BW6: Price | BX6: Line Price | BY6: Connection Ancillary 3 | BZ6: Connection Ancillary 3 Quantity | CA6: Price | CB6: Line Price | CC6: Connection Ancillary 4 Type | CD6: Connection Ancillary 4 Quantity | CE6: Price | CF6: Line Price | CG6: Connection Ancillary 5 Type | CH6: Connection Ancillary 5 Quantity | CI6: Price | CJ6: Line Price | CK6: Connection Ancillary 6 Type | CL6: Connection Ancillary 6 Quantity | CM6: Price | CN6: Line Price | CO6: Connection Ancillary 7 Type | CP6: Connection Ancillary 7 Quantity | CQ6: Price | CR6: Line Price | CS6: Price
A7: 1 | B7: Trial Crossing 1 | C7: 7.2 | D7: =IF(C7="","",ROUNDUP(C7/1.8,0)*1.8) -> 7.2 | E7: 2 | F7: 49E1 | G7: SB8 | H7: K-Type | I7: 5mm | J7: N/A | K7: 1520 | L7: Yes | M7: 45 | N7: WFP (>565 <=840) | O7: Rubber Edge Beam | P7: 100 | Q7: Medium to Heavy (Medium use - Mostly Cars) | R7: =CONCATENATE(W7,X7,Y7,Z7,AA7,AB7,AC7) -> LO H K PC | S7: =IF(R7="","Selection doesn’t allow a System - Please Contact RHR",R7) -> LO H K PC | T7: LO | W7: =IF(Q7=List!F2,"BP ",IF(L7="No","",IF(OR(Q7=List!F8,'Order Summary'!Q7=List!F7),"",IF(AND(M7>=60,M7<=120,P7<=70),"BP ","")))) | X7: =IF(AND(L7="yes",Q7<>"Ultra Heavy (Mining/City Centre Dual Carriageway)"),"LO ","") -> LO | Y7: =IF(OR(Q7=List!F3,'Order Summary'!Q7=List!F4),"LOL ","") | Z7: =IF(AND(L7="yes",Q7<>"Ultra Heavy (Mining/City Centre Dual Carriageway)"),"H K ","") -> H K | AA7: =IF(OR(Q7=List!F3,'Order Summary'!Q7=List!F4),"H L K ","") | AB7: =IF(AND(ISNUMBER(SEARCH("Ultra",Q7)),L7="Yes"),"SF2 K ","") | AC7: PC | AE7: =IF(ISNUMBER(SEARCH("Pedestrian",Q7)),"P(B)","") | AF7: =IF(AND(T7="BP ",ISNUMBER(SEARCH("Agri",Q7))),"A(B)",IF(AND(T7="LO ",ISNUMBER(SEARCH("Agri",Q7))),"A(B)","")) | AG7: =IF(OR(ISNUMBER(SEARCH("Rail Road Access",Q7)),L7="No"),"JV",IF(AND(T7="H K ",ISNUMBER(SEARCH("Agri",Q7))),"JV","")) | AH7: =IF(Q7<>List!F5,"",IF(OR(T7="BP ",T7="LO "),"N","")) | AI7: =IF(AND(ISNUMBER(SEARCH("K",T7)),OR(Q7=List!F5,'Order Summary'!Q7=List!F6,'Order Summary'!Q7=List!F7,'Order Summary'!Q7=List!F8,)),"TC",IF(AND(T7="BP ",Q7=List!F6),"TC",IF(AND(ISNUMBER(SEARCH("LO",T7)),OR('Order Summary'!Q7=List!F6,'Order Summary'!Q7=List!F7,'Order Summary'!Q7=List!F8,)),"TC",""))) -> TC | AJ7: =CONCATENATE(AE7,AF7,AG7,AH7,AI7) -> TC | AL7: =IF(K7<=1420,"NGP",IF(K7>=1455,"WGP","GP")) -> WGP | AM7: =IF($T7="BP ",CONCATENATE($AL7," ",$AE7,$AF7,$AG7,$AH7,$AI7," "),CONCATENATE($AL7," ",$AE7,$AF7,$AG7,$AH7,$AI7," ",$T7)) -> WGP TC LO | AN7: =(D7/1.8*2)*E7 -> 16 | AO7: =IF(I2="€uro",_xlfn.XLOOKUP(AM7,'PRICE LIST'!$D$4:$D$153,'PRICE LIST'!$F$4:$F$153),"") -> 927.2 | AQ7: =IF(ISNUMBER(SEARCH("SWFP",N7)),"SWFP",IF(ISNUMBER(SEARCH("WFP",N7)),"WFP",IF(N7="Gauge Panel Only","","FP"))) -> WFP | AR7: =IF($T7="BP ",CONCATENATE($AQ7," ",$AE7,$AF7,$AG7,$AH7,$AI7," "),CONCATENATE($AQ7," ",$AE7,$AF7,$AG7,$AH7,$AI7," ",$T7)) -> WFP TC LO | AS7: =IF(AQ7="","",(D7/1.8*2)*E7) -> 16 | AT7: =IF(I2="€uro",_xlfn.XLOOKUP(AR7,'PRICE LIST'!$D$4:$D$153,'PRICE LIST'!$F$4:$F$153),"") -> 839.1 | AV7: =IF(ISNUMBER(SEARCH("Rubber Edge Beam",O7)),"REB TC","") -> REB TC | AW7: =IF(AV7="","",AS7) -> 16 | AX7: =IF($I$2="€uro",_xlfn.XLOOKUP(AV7,'PRICE LIST'!$D$3:$D$153,'PRICE LIST'!$F$3:$F$153),"") -> 365.25 | AZ7: =IF(ISNUMBER(SEARCH("PC",T7)),"Link Chain Guard",IF(ISNUMBER(SEARCH("K",T7)),"Link Chain Guard",IF(ISNUMBER(SEARCH("BP",T7)),"Baseplated Chain Guard",IF(ISNUMBER(SEARCH("LOL",T7)),"Interlocker Chain Guard",IF(ISNUMBER(SEARCH("LO",T7)),"CONNECT CHAIN GUARD",""))))) -> CONNECT CHAIN GUARD | BA7: =E7*2 -> 4 | BB7: =IF($I$2="€uro",_xlfn.XLOOKUP(AZ7,'PRICE LIST'!$I$4:$I$55,'PRICE LIST'!$K$4:$K$55)) -> 87.8 | BC7: =BA7*BB7 -> 351.2 | BD7: =IF(AND(T7="pc",N7="FP (<=436 >=565)"),"Strand Movement Restrictor",IF(ISNUMBER(SEARCH("K",T7)),"Link End Restraint",IF(ISNUMBER(SEARCH("LO",T7)),"Connect End Restraint",IF(AND(T7="BP ",M7<=70),"Movement Restrictor","")))) -> Connect End Restraint | BE7: =IF(BD7="","",IF(BD7="Strand Movement Restrictor",4*E7,IF(N7="Gauge Panel Only",E7*4,E7*8))) -> 16 | BF7: =IF($I$2="€uro",_xlfn.XLOOKUP(BD7,'PRICE LIST'!$I$4:$I$55,'PRICE LIST'!$K$4:$K$55)) -> 227.55 | BH7: =IF(ISNUMBER(SEARCH("PVC",O7)),"PVC AEB @ 3.6m",IF(ISNUMBER(SEARCH("Steel",O7)),"Steel AEB @ 3.6m","")) | BI7: =IF(BH7="","",_xlfn.XLOOKUP(D7,List!K3:K114,List!L3:L114)*'Order Summary'!E7) | BJ7: =IF($I$2="€uro",_xlfn.XLOOKUP(BH7,'PRICE LIST'!$I$4:$I$55,'PRICE LIST'!$K$4:$K$55)) -> #N/A | BL7: =IF(ISNUMBER(SEARCH("PVC",O7)),"PVC AEB @ 1.8m",IF(ISNUMBER(SEARCH("Steel",O7)),"Steel AEB @ 1.8m","")) | BM7: =IF(BL7="","",_xlfn.XLOOKUP(D7,List!K3:K114,List!M3:M114,0)*'Order Summary'!E7) | BN7: =IF($I$2="€uro",_xlfn.XLOOKUP(BL7,'PRICE LIST'!$I$4:$I$55,'PRICE LIST'!$K$4:$K$55)) -> #N/A | BQ7: =IF(T7="PC","Sheath Guard",IF(T7="BP ","ZR Turret",IF(T7="LO ","",IF(OR(T7="H K ",T7="SF2 K ",T7="h l k "),"Link Connector",IF(T7="LOL ","Gauge Connecting Plates",""))))) | BR7: =IF(AND(BQ7="Sheath Guard",ISNUMBER(SEARCH("SWFP",N7))),6*E7,IF(AND(BQ7="Sheath Guard",ISNUMBER(SEARCH("Gauge",N7))),2*E7,IF(BQ7="Sheath Guard",4*E7,IF(AND(BQ7="Link Connector",N7="Gauge Panel Only"),((D7/1.8)-1)*2*E7,IF(BQ7="Link Connector",((D7/1.8)-1)*4*E7,IF(BQ7="Gauge Connecting Plates",((D7/1.8)-1)*E7,IF(AND(BQ7="ZR Turret",D7<=1.8),"",IF(AND(BQ7="ZR Turret",N7="Gauge Panel Only"),((((D7/1.8)-1)*2)*E7)-BV7,IF(BQ7="ZR Turret",((((D7/1.8)-1)*4)*E7)-BV7,""))))))))) | BS7: =IF($I$2="€uro",_xlfn.XLOOKUP(BQ7,'PRICE LIST'!$I$4:$I$55,'PRICE LIST'!$K$4:$K$55)) -> #N/A | BU7: =IF(BQ7="Gauge Connecting Plates","Field Connecting Plates",IF(T7="H L K ","Link Gauge Connecting Plates",IF(T7="PC","ZR Winged 1UT",IF(BQ7="ZR Turret","ZR Winged","")))) | BV7: =IF(BD7="Strand Movement Restrictor",2*E7,IF(T7="PC",4*E7,IF(BU7="Field Connecting Plates",BR7*2,IF(BU7="Link Gauge Connecting Plates",(((D7/1.8)-1)*E7),IF(AND(BU7="ZR Winged",N7="Gauge Panel Only"),_xlfn.XLOOKUP(D7,List!K2:K114,List!N2:N114)/2*E7,IF(BU7="ZR Winged",_xlfn.XLOOKUP(D7,List!$K$3:$K$114,List!$N$3:$N$114)*'Order Summary'!E7,"")))))) | BW7: =IF($I$2="€uro",_xlfn.XLOOKUP(BU7,'PRICE LIST'!$I$4:$I$55,'PRICE LIST'!$K$4:$K$55)) -> #N/A | BY7: {=IF(T7="PC",_xlfn.XLOOKUP(D7,Table1[[#All],[Crossing Length]],Table1[[#All],[Strand Length]]),"")} | BZ7: =IF(AND(ISNUMBER(SEARCH("Strand",BY7)),ISNUMBER(SEARCH("SWFP",N7))),6*E7,IF(AND(ISNUMBER(SEARCH("Strand",BY7)),ISNUMBER(SEARCH("Gauge",N7))),2*E7,IF(ISNUMBER(SEARCH("Strand",BY7)),4*E7,""))) | CA7: =IF($I$2="€uro",_xlfn.XLOOKUP(BY7,'PRICE LIST'!$I$4:$I$55,'PRICE LIST'!$K$4:$K$55)) -> #N/A | CC7: =IF(T7="PC","Gauge Connecting Plates PC","") | CD7: =IF(CC7="Gauge Connecting Plates PC",((((D7/1.8)-1)*2)*E7),"") | CE7: =IF($I$2="€uro",_xlfn.XLOOKUP(CC7,'PRICE LIST'!$I$4:$I$55,'PRICE LIST'!$K$4:$K$55)) -> #N/A | CG7: =IF(AND(T7="PC",ISNUMBER(SEARCH("436",N7))),"Field Connecting Plates PC",IF(AND(T7="PC",ISNUMBER(SEARCH("SWFP",N7))),"Super Field Connecting Plates PC",IF(AND(T7="PC",ISNUMBER(SEARCH("WFP",N7))),"Wide Field Connecting Plates PC",""))) | CH7: =IF(ISNUMBER(SEARCH("connecting",CG7)),((((D7/1.8)-1)*2)*E7),"") | CI7: =IF($I$2="€uro",_xlfn.XLOOKUP(CG7,'PRICE LIST'!$I$4:$I$55,'PRICE LIST'!$K$4:$K$55)) -> #N/A | CK7: =IF(T7="PC","Galvanised GP End Plates PC","") | CL7: =IF(CK7="","",E7*2) | CM7: =IF($I$2="€uro",_xlfn.XLOOKUP(CK7,'PRICE LIST'!$I$4:$I$55,'PRICE LIST'!$K$4:$K$55)) -> #N/A | CO7: =IF(AND(T7="PC",ISNUMBER(SEARCH("SWFP",N7))),"Galvanised SWFP End Plates PC",IF(AND(T7="PC",ISNUMBER(SEARCH("WFP",N7))),"Galvanised WFP End Plates PC",IF(AND(T7="PC",ISNUMBER(SEARCH("FP",N7))),"Galvanised FP End Plates PC",""))) | CP7: =IF(CO7="","",E7*2) | CQ7: =IF($I$2="€uro",_xlfn.XLOOKUP(CO7,'PRICE LIST'!$I$4:$I$55,'PRICE LIST'!$K$4:$K$55)) -> #N/A | CS7: =IF($I$2="€uro",_xlfn.XLOOKUP(CS5,'PRICE LIST'!$I$4:$I$55,'PRICE LIST'!$K$4:$K$55)) -> 71.8
A8: 2 | C8: 10.8 | D8: =IF(C8="","",ROUNDUP(C8/1.8,0)*1.8) -> 10.8 | E8: 1
A9: 3 | D9: =IF(C9="","",ROUNDUP(C9/1.8,0)*1.8)
A10: 4 | D10: =IF(C10="","",ROUNDUP(C10/1.8,0)*1.8)
A11: 5 | D11: =IF(C11="","",ROUNDUP(C11/1.8,0)*1.8)
A12: 6 | D12: =IF(C12="","",ROUNDUP(C12/1.8,0)*1.8)
A13: 7 | D13: =IF(C13="","",ROUNDUP(C13/1.8,0)*1.8)
A14: 8 | D14: =IF(C14="","",ROUNDUP(C14/1.8,0)*1.8)
A15: 9 | D15: =IF(C15="","",ROUNDUP(C15/1.8,0)*1.8)
A16: 10 | D16: =IF(C16="","",ROUNDUP(C16/1.8,0)*1.8)
A17: 11 | D17: =IF(C17="","",ROUNDUP(C17/1.8,0)*1.8)
A18: 12 | D18: =IF(C18="","",ROUNDUP(C18/1.8,0)*1.8)
A19: 13 | D19: =IF(C19="","",ROUNDUP(C19/1.8,0)*1.8)
A20: 14 | D20: =IF(C20="","",ROUNDUP(C20/1.8,0)*1.8)
... A36: 30 | D36: =IF(C36="","",ROUNDUP(C36/1.8,0)*1.8)

Sheet Quote
C1: Crossing Name | D1: ='Order Summary'!C3 -> Quote Trial 1
C2: Quote Date: | D2: =TODAY() -> 45971
C3: Valid Until: | D3: =D2+90 -> 46061
A5: Crossing Type 1 | C5: ='Order Summary'!B7 -> Trial Crossing 1
A6: =CONCATENATE('Order Summary'!E7," x ",'Order Summary'!D7,"m ",_xlfn.XLOOKUP('Order Summary'!T7,List!$G$12:$G$18,List!$F$12:$F$18)," ",_xlfn.XLOOKUP('Order Summary'!AJ7,List!$G$21:$G$25,List!$F$21:$F$25)," CROSSING(s)") -> 2 x 7.2m LOOP EXTREME CROSSING(s)
A7: Rail | B7: ='Order Summary'!F7 -> 49E1 | C7: Rail Pad | D7: ='Order Summary'!I7 -> 5mm | E7: Sleeper Spacing | F7: =IF('Order Summary'!L7="Yes","600mm","Varies") -> 600mm
A8: Sleeper | B8: ='Order Summary'!G7 -> SB8 | C8: Isolation Pad | D8: ='Order Summary'!J7 -> N/A | E8: Crossing Skew | F8: ='Order Summary'!M7 -> 45
A9: Clip | B9: ='Order Summary'!H7 -> K-Type | C9: Gauge | D9: ='Order Summary'!K7 -> 1520 | E9: Road Speed | F9: ='Order Summary'!P7 -> 100
A11: Material | B11: Nature | C11: Code | D11: Quantity | E11: Price/Unit | F11: Sub-Total
A12: =IF(C12="","",IF(ISNUMBER(SEARCH("TC",C12)),"EXTREME",IF(ISNUMBER(SEARCH("P(B)",C12)),"PEDESTRIAN",IF(ISNUMBER(SEARCH("A(B)",C12)),"AGRICULTURAL",IF(ISNUMBER(SEARCH("JV",C12)),"RRAP","ROAD"))))) -> EXTREME | B12: =IF(C12="","",IF(ISNUMBER(SEARCH("WGP",C12)),"WIDE GAUGE PANEL",IF(ISNUMBER(SEARCH("NGP",C12)),"NARROW GAUGE PANEL","GAUGE PANEL"))) -> WIDE GAUGE PANEL | C12: =IF('Order Summary'!AM7="","",'Order Summary'!AM7) -> WGP TC LO | D12: =IF(C12="","",'Order Summary'!AN7) -> 16 | E12: ='Order Summary'!AO7 -> 927.2 | F12: =IF(D12="","",D12*E12) -> 14835.2
A13: =IF(C13="","",IF(ISNUMBER(SEARCH("TC",C13)),"EXTREME",IF(ISNUMBER(SEARCH("P(B)",C13)),"PEDESTRIAN",IF(ISNUMBER(SEARCH("A(B)",C13)),"AGRICULTURAL",IF(ISNUMBER(SEARCH("JV",C13)),"RRAP","ROAD"))))) -> EXTREME | B13: =IF(C13="","",IF(ISNUMBER(SEARCH("SWFP",C13)),"SUPER WIDE FIELD PANEL",IF(ISNUMBER(SEARCH("WFP",C13)),"WIDE FIELD PANEL","FIELD PANEL"))) -> WIDE FIELD PANEL | C13: =IF('Order Summary'!AR7="","",'Order Summary'!AR7) -> WFP TC LO | D13: =IF(C13="","",'Order Summary'!AS7) -> 16 | E13: =IF(D13="","",'Order Summary'!AT7) -> 839.1 | F13: =IF(D13="","",D13*E13) -> 13425.6
A14: =IF(C14="","",IF(ISNUMBER(SEARCH("TC",C14)),"EXTREME",IF(ISNUMBER(SEARCH("P(B)",C14)),"PEDESTRIAN",IF(ISNUMBER(SEARCH("A(B)",C14)),"AGRICULTURAL",IF(ISNUMBER(SEARCH("JV",C14)),"RRAP","ROAD"))))) -> EXTREME | B14: =IF(C14="","","RUBBER EDGE BEAM") -> RUBBER EDGE BEAM | C14: =IF('Order Summary'!AV7="","",'Order Summary'!AV7) -> REB TC | D14: =IF(C14="","",'Order Summary'!AW7) -> 16 | E14: =IF(B14="","",'Order Summary'!AX7) -> 365.25 | F14: =IF(D14="","",D14*E14) -> 5844
B15: =IF('Order Summary'!AZ7="","",'Order Summary'!AZ7) -> CONNECT CHAIN GUARD | C15: =IF(B15="","",_xlfn.XLOOKUP(B15,List!$B$12:$B$15,List!$C$12:$C$15)) -> CG CONNECT | D15: =IF(B15="","",'Order Summary'!BA7) -> 4 | E15: =IF(B15="","",'Order Summary'!BB7) -> 87.8 | F15: =IF(D15="","",D15*E15) -> 351.2
B16: =IF('Order Summary'!BD7="","",'Order Summary'!BD7) -> Connect End Restraint | C16: =IF(B16="","",_xlfn.XLOOKUP(B16,List!$B$17:$B$20,List!$C$17:$C$20)) -> ER Connect | D16: =IF(B16="","",'Order Summary'!BE7) -> 16 | E16: =IF(B16="","",'Order Summary'!BF7) -> 227.55 | F16: =IF(D16="","",D16*E16) -> 3640.8
B17: =IF('Order Summary'!BI7="","",'Order Summary'!BH7) | C17: =IF(B17="","",_xlfn.XLOOKUP(B17,List!$B$22:$B$25,List!$C$22:$C$25)) | D17: =IF(B17="","",'Order Summary'!BI7) | E17: =IF(B17="","",'Order Summary'!BJ7) | F17: =IF(D17="","",D17*E17)
B18: =IF('Order Summary'!BM7=0,"",'Order Summary'!BL7) | C18: =IF(B18="","",_xlfn.XLOOKUP(B18,List!$B$22:$B$25,List!$C$22:$C$25)) | D18: =IF(B18="","",'Order Summary'!BM7) | E18: =IF(B18="","",'Order Summary'!BN7) | F18: =IF(D18="","",D18*E18)
B19: =IF('Order Summary'!BQ7="","",'Order Summary'!BQ7) | C19: =IF(Quote!B19="","",_xlfn.XLOOKUP(B19,List!$B$28:$B$31,List!$C$28:$C$31)) | D19: =IF(B19="","",'Order Summary'!BR7) | E19: =IF(B19="","",'Order Summary'!BS7) | F19: =IF(D19="","",D19*E19)
B20: =IF('Order Summary'!BU7="","",'Order Summary'!BU7) | C20: =IF(B20="","",_xlfn.XLOOKUP(B20,List!$B$33:$B$36,List!$C$33:$C$36)) | D20: =IF(B20="","",'Order Summary'!BV7) | E20: =IF(B20="","",'Order Summary'!BW7) | F20: =IF(D20="","",D20*E20)
B21: =IF(AND(B14="Rubber Edge Beam",'Order Summary'!D7>=1.81),"Rubber Edge Beam Baseplate","") -> Rubber Edge Beam Baseplate | C21: =IF(B21="","","REB Plain LCP") -> REB Plain LCP | D21: =IF(B21="","",(((('Order Summary'!D7/1.8)-1)*2)*'Order Summary'!E7)) -> 12 | E21: =IF(B21="","",'Order Summary'!CS7) -> 71.8 | F21: =IF(D21="","",D21*E21) -> 861.6
B22: =IF('Order Summary'!BY7="","",'Order Summary'!BY7) | C22: =IF(ISNUMBER(SEARCH("Strand",B22)),"C/W Live & Dead End","") | D22: =IF(B22="","",'Order Summary'!BZ7) | F22: =IF(D22="","",D22*E22)
B23: =IF('Order Summary'!CC7="","",'Order Summary'!CC7) | C23: =IF(B23="","",_xlfn.XLOOKUP(B23,List!B38,List!C38)) | D23: =IF(B23="","",'Order Summary'!CD7) | F23: =IF(D23="","",D23*E23)
B24: =IF('Order Summary'!CG7="","",'Order Summary'!CG7) | C24: =IF(B24="","",_xlfn.XLOOKUP(B24,List!$B$40:$B$42,List!$C$40:$C$42)) | D24: =IF(B24="","",'Order Summary'!CH7) | F24: =IF(D24="","",D24*E24)
B25: =IF('Order Summary'!CK7="","",'Order Summary'!CK7) | C25: =IF(B25="","",_xlfn.XLOOKUP(B25,List!$B$44:$B$47,List!$C$44:$C$47)) | D25: =IF(B25="","",'Order Summary'!CL7) | F25: =IF(D25="","",D25*E25)
B26: =IF('Order Summary'!CO7="","",'Order Summary'!CO7) | C26: =IF(B26="","",_xlfn.XLOOKUP(B26,List!$B$44:$B$47,List!$C$44:$C$47)) | D26: =IF(B26="","",'Order Summary'!CP7) | F26: =IF(D26="","",D26*E26)
E28: =SUM(F12:F26) -> 38958.4

Sheet PRICE LIST
I1: Ancillaries
E2: Cost Price | F2: Euro Price List
D3: REB TC | F3: 365.25 | J3: Cost Price | K3: Euro Price List
B4: Baseplated Panels | D4: NGP P(B) | E4: 183.81 | F4: 349.55 | I4: CONNECT CHAIN GUARD | K4: 87.8
D5: NGP A(B) | I5: LINK CHAIN GUARD | K5: 59.05
D6: NGP JV | F6: 387.55 | I6: BASEPLATED CHAIN GUARD | K6: 54.9
D7: NGP N | F7: 434.2 | I7: INTERLOCKER CHAIN GUARD | K7: 111.4
D8: NGP TC | F8: 482.45 | I8: Connect End Restraint | K8: 227.55
D9: GP P(B) | F9: 401.05 | I9: Link End Restraint | K9: 227.45
D10: GP A(B) | F10: 488.85 | I10: Movement Restrictor | K10: 190.7
D11: GP JV | F11: 454.35 | I11: Strand Movement Restrictor | K11: 190.7
D12: GP N | F12: 496.2 | I12: Steel AEB @ 3.6m | K12: 349.5
D13: GP TC | F13: 551.35 | I13: Steel AEB @ 1.8m | K13: 213.05
D14: WGP P(B) | F14: 438.55 | I14: PVC AEB @ 3.6m | K14: 152.45
D15: WGP A(B) | F15: 536.05 | I15: PVC AEB @ 1.8m | K15: 122.15
D16: WGP JV | F16: 488.9 | I16: Link Connector | K16: 127.5
D17: WGP N | F17: 540.7 | I17: ZR Turret | K17: 46.8
D18: WGP TC | F18: 600.75 | I18: Sheath Guard
D19: FP P(B) | F19: 333.55 | I19: Gauge Connecting PlateS | K19: 122.6
D20: FP A(B) | F20: 427.05 | I20: ZR Winged | K20: 59.9
D21: FP JV | F21: 426.35 | I21: ZR Winged 1UT | K21: 59.9
D22: FP N | F22: 421.05 | I22: Link Gauge Connecting Plates
D23: FP TC | F23: 467.75 | I23: Field Connecting Plates | K23: 46.65
D24: WFP P(B) | F24: 389.75 | I24: Gauge Connecting Plates PC
D25: WFP A(B) | F25: 476.35 | I25: Field Connecting Plates PC
D26: WFP JV | F26: 447.45 | I26: Super Field Connecting Plates PC
D27: WFP N | F27: 496.1 | I27: Wide Field Connecting Plates PC
D28: WFP TC | F28: 551.2 | I28: Galvanised GP End Plates PC
D29: SWFP P(B) | F29: 430.8 | I29: Galvanised SWFP End Plates PC
D30: SWFP A(B) | I30: Galvanised WFP End Plates PC
D31: SWFP JV | F31: 496.75 | I31: Galvanised FP End Plates PC
D32: SWFP N | I32: Rubber Edge Beam Baseplate | K32: 71.8
D33: SWFP TC | I33: 15.7mm Strand @ 4.05m
B34: LOOP | D34: NGP P(B) LO | F34: 512.7 | I34: 15.7mm Strand @ 5.85m
D35: NGP A(B) LO | I35: 15.7mm Strand @ 7.65m
D36: NGP JV LO | F36: 641.05 | I36: 15.7mm Strand @ 9.45m
D37: NGP N LO | I37: 15.7mm Strand @ 11.25m
D38: NGP TC LO | I38: 15.7mm Strand @ 13.05m
D39: GP P(B) LO | F39: 649.05 | I39: 15.7mm Strand @ 14.85m
D40: GP A(B) LO | I40: 15.7mm Strand @ 16.65m
...

Sheet List
K1: AEB | N1: Winged Baseplate Quantity
B2: FP (<=436 >=565) | D2: Steel AEB | F2: Pedestrian & Cycles Only | H2: Yes | K2: Length | L2: 3.6 | M2: 1.8 | N2: ZRW
B3: WFP (>565 <=840) | D3: PVC AEB | F3: Agricultural Machinery | H3: No | J3: 1.8 | K3: 0.9 | L3: 0 | M3: =IF(J3=1.8,2,0) -> 2 | N3: 4
B4: SWFP (>840mm) | D4: Rubber Edge Beam | F4: Rail Road Access Point | J4: 1.8 | K4: 1.8 | L4: 0 | M4: =IF(J4=1.8,2,0) -> 2 | N4: 4
B5: Gauge Panel Only | D5: Customers Concrete Edge Beam | F5: Light to Medium (Low Use Country Roads) | J5: 1.8 | K5: 2.7 | L5: 2 | M5: =IF(J5=1.8,2,0) -> 2 | N5: 4
D6: N/A | F6: Medium to Heavy (Medium use - Mostly Cars) | K6: 3.6 | L6: =ROUNDDOWN(K6/3.6,0)*2 -> 2 | M6: =IF(J6=1.8,2,0) -> 0 | N6: 4
F7: Heavy (High Use of Trucks and Cars) | J7: 1.8 | K7: 4.5 | L7: =ROUNDDOWN(K7/3.6,0)*2 -> 2 | M7: =IF(J7=1.8,2,0) -> 2 | N7: 4
F8: Ultra Heavy (Mining/City Centre Dual Carriageway) | J8: 1.8 | K8: 5.4 | L8: =ROUNDDOWN(K8/3.6,0)*2 -> 2 | M8: =IF(J8=1.8,2,0) -> 2 | N8: 4
J9: 1.8 | K9: 6.3 | L9: =ROUNDDOWN(K9/3.6,0)*2 -> 2 | M9: =IF(J9=1.8,2,0) -> 2 | N9: 4
K10: 7.2 | L10: =ROUNDDOWN(K10/3.6,0)*2 -> 4 | M10: =IF(J10=1.8,2,0) -> 0 | N10: 4
J11: 1.8 | K11: 8.1 | L11: =ROUNDDOWN(K11/3.6,0)*2 -> 4 | M11: =IF(J11=1.8,2,0) -> 2 | N11: 4
B12: CONNECT CHAIN GUARD | C12: CG CONNECT | F12: BASEPLATED | G12: BP | J12: 1.8 | K12: 9 | L12: =ROUNDDOWN(K12/3.6,0)*2 -> 4 | M12: =IF(J12=1.8,2,0) -> 2 | N12: 4
B13: LINK CHAIN GUARD | C13: CG LINK | F13: LOOP | G13: LO | J13: 1.8 | K13: 9.9 | L13: =ROUNDDOWN(K13/3.6,0)*2 -> 4 | M13: =IF(J13=1.8,2,0) -> 2 | N13: 4
B14: BASEPLATED CHAIN GUARD | C14: CG BASEPLATED | F14: LOOP INTERLOCKER | G14: LOL | K14: 10.8 | L14: =ROUNDDOWN(K14/3.6,0)*2 -> 6 | M14: =IF(J14=1.8,2,0) -> 0 | N14: 4
B15: INTERLOCKER CHAIN GUARD | C15: CG INTERLOCKING | F15: LINK | G15: H K | J15: 1.8 | K15: 11.7 | L15: =ROUNDDOWN(K15/3.6,0)*2 -> 6 | M15: =IF(J15=1.8,2,0) -> 2 | N15: 8
F16: LINK INTERLOCKER | G16: H L K | J16: 1.8 | K16: 12.6 | L16: =ROUNDDOWN(K16/3.6,0)*2 -> 6 | M16: =IF(J16=1.8,2,0) -> 2 | N16: 8
B17: Connect End Restraint | C17: ER Connect | F17: TITAN | G17: SF2 K | J17: 1.8 | K17: 13.5 | L17: =ROUNDDOWN(K17/3.6,0)*2 -> 6 | M17: =IF(J17=1.8,2,0) -> 2 | N17: 8
B18: Link End Restraint | C18: ER Link | F18: STRANDLOCK | G18: PC | K18: 14.4 | L18: =ROUNDDOWN(K18/3.6,0)*2 -> 8 | M18: =IF(J18=1.8,2,0) -> 0 | N18: 8
B19: Movement Restrictor | C19: MR | J19: 1.8 | K19: 15.3 | L19: =ROUNDDOWN(K19/3.6,0)*2 -> 8 | M19: =IF(J19=1.8,2,0) -> 2 | N19: 8
B20: Strand Movement Restrictor | C20: MR Strand | J20: 1.8 | K20: 16.2 | L20: =ROUNDDOWN(K20/3.6,0)*2 -> 8 | M20: =IF(J20=1.8,2,0) -> 2 | N20: 8
F21: EXTREME | G21: TC | J21: 1.8 | K21: 17.1 | L21: =ROUNDDOWN(K21/3.6,0)*2 -> 8 | M21: =IF(J21=1.8,2,0) -> 2 | N21: 8
B22: Steel AEB @ 3.6m | C22: SAEB 3.6m | F22: ROAD | G22: N | K22: 18 | L22: =ROUNDDOWN(K22/3.6,0)*2 -> 10 | M22: =IF(J22=1.8,2,0) -> 0 | N22: 12
B23: Steel AEB @ 1.8m | C23: SAEB 1.8m | F23: RRAP | G23: JV | J23: 1.8 | K23: 18.9 | L23: =ROUNDDOWN(K23/3.6,0)*2 -> 10 | M23: =IF(J23=1.8,2,0) -> 2 | N23: 12
B24: PVC AEB @ 3.6m | C24: PVC AEB @ 3.6m | F24: AGRICULTURAL | G24: A(B) | J24: 1.8 | K24: 19.8 | L24: =ROUNDDOWN(K24/3.6,0)*2 -> 10 | M24: =IF(J24=1.8,2,0) -> 2 | N24: 12
B25: PVC AEB @ 1.8m | C25: PVC AEB @ 1.8m | F25: PEDESTRIAN | G25: P(B) | J25: 1.8 | K25: 20.7 | L25: =ROUNDDOWN(K25/3.6,0)*2 -> 10 | M25: =IF(J25=1.8,2,0) -> 2 | N25: 12
K26: 21.6 | L26: =ROUNDDOWN(K26/3.6,0)*2 -> 12 | M26: =IF(J26=1.8,2,0) -> 0 | N26: 12
J27: 1.8 | K27: 22.5 | L27: =ROUNDDOWN(K27/3.6,0)*2 -> 12 | M27: =IF(J27=1.8,2,0) -> 2 | N27: 12
B28: Link Connector | C28: Link Connector | E28: Crossing Length | F28: Strand Length | J28: 1.8 | K28: 23.4 | L28: =ROUNDDOWN(K28/3.6,0)*2 -> 12 | M28: =IF(J28=1.8,2,0) -> 2 | N28: 12
B29: ZR Turret | C29: ZR | E29: 3.6 | F29: =CONCATENATE("15.7mm Strand @ ",E29+0.45,"m") -> 15.7mm Strand @ 4.05m | J29: 1.8 | K29: 24.3 | L29: =ROUNDDOWN(K29/3.6,0)*2 -> 12 | M29: =IF(J29=1.8,2,0) -> 2 | N29: 12
B30: Sheath Guard | C30: PC SG | E30: 5.4 | F30: =CONCATENATE("15.7mm Strand @ ",E30+0.45,"m") -> 15.7mm Strand @ 5.85m | K30: 25.2 | L30: =ROUNDDOWN(K30/3.6,0)*2 -> 14 | M30: =IF(J30=1.8,2,0) -> 0 | N30: 12
B31: Gauge Connecting PlateS | C31: GP LOL Connect | E31: 7.2 | F31: =CONCATENATE("15.7mm Strand @ ",E31+0.45,"m") -> 15.7mm Strand @ 7.65m | J31: 1.8 | K31: 26.1 | L31: =ROUNDDOWN(K31/3.6,0)*2 -> 14 | M31: =IF(J31=1.8,2,0) -> 2 | N31: 16
E32: 9 | F32: =CONCATENATE("15.7mm Strand @ ",E32+0.45,"m") -> 15.7mm Strand @ 9.45m | J32: 1.8 | K32: 27 | L32: =ROUNDDOWN(K32/3.6,0)*2 -> 14 | M32: =IF(J32=1.8,2,0) -> 2 | N32: 16
B33: ZR Winged | C33: ZRW | E33: 10.8 | F33: =CONCATENATE("15.7mm Strand @ ",E33+0.45,"m") -> 15.7mm Strand @ 11.25m | J33: 1.8 | K33: 27.9 | L33: =ROUNDDOWN(K33/3.6,0)*2 -> 14 | M33: =IF(J33=1.8,2,0) -> 2 | N33: 16
B34: ZR Winged 1UT | C34: ZRW 1UT | E34: 12.6 | F34: =CONCATENATE("15.7mm Strand @ ",E34+0.45,"m") -> 15.7mm Strand @ 13.05m | K34: 28.8 | L34: =ROUNDDOWN(K34/3.6,0)*2 -> 16 | M34: =IF(J34=1.8,2,0) -> 0 | N34: 16
B35: Link Gauge Connecting Plates | C35: HLK GP Connect Plate | E35: 14.4 | F35: =CONCATENATE("15.7mm Strand @ ",E35+0.45,"m") -> 15.7mm Strand @ 14.85m | J35: 1.8 | K35: 29.7 | L35: =ROUNDDOWN(K35/3.6,0)*2 -> 16 | M35: =IF(J35=1.8,2,0) -> 2 | N35: 16
B36: Field Connecting Plates | C36: FP LOL Connect | E36: 16.2 | F36: =CONCATENATE("15.7mm Strand @ ",E36+0.45,"m") -> 15.7mm Strand @ 16.65m | J36: 1.8 | K36: 30.6 | L36: =ROUNDDOWN(K36/3.6,0)*2 -> 16 | M36: =IF(J36=1.8,2,0) -> 2 | N36: 16
E37: 18 | F37: =CONCATENATE("15.7mm Strand @ ",E37+0.45,"m") -> 15.7mm Strand @ 18.45m | J37: 1.8 | K37: 31.5 | L37: =ROUNDDOWN(K37/3.6,0)*2 -> 16 | M37: =IF(J37=1.8,2,0) -> 2 | N37: 16
B38: Gauge Connecting Plates PC | C38: GP PC Connect | E38: 19.8 | F38: =CONCATENATE("15.7mm Strand @ ",E38+0.45,"m") -> 15.7mm Strand @ 20.25m | K38: 32.4 | L38: =ROUNDDOWN(K38/3.6,0)*2 -> 18 | M38: =IF(J38=1.8,2,0) -> 0 | N38: 20
E39: 21.6 | F39: =CONCATENATE("15.7mm Strand @ ",E39+0.45,"m") -> 15.7mm Strand @ 22.05m | J39: 1.8 | K39: 33.3 | L39: =ROUNDDOWN(K39/3.6,0)*2 -> 18 | M39: =IF(J39=1.8,2,0) -> 2 | N39: 20
B40: Field Connecting Plates PC | C40: FP PC Connect | E40: 23.4 | F40: =CONCATENATE("15.7mm Strand @ ",E40+0.45,"m") -> 15.7mm Strand @ 23.85m | J40: 1.8 | K40: 34.2 | L40: =ROUNDDOWN(K40/3.6,0)*2 -> 18 | M40: =IF(J40=1.8,2,0) -> 2 | N40: 20
...
